<?xml version="1.0" ?>
<!-- =================================================================================== -->
<!-- |    This document was autogenerated by xacro from /home/dk/workspace/rpc_ws/src/rpc_ros/description/optimo_description/urdf/optimo.urdf.xacro | -->
<!-- |    EDITING THIS FILE BY HAND IS NOT RECOMMENDED                                 | -->
<!-- =================================================================================== -->
<!-- URDF for the standalone Optimo 7-DOF arm, including controls -->
<robot name="optimo">
  <mujoco>
    <compiler meshdir="meshes/"/>
  </mujoco>
  <material name="white">
    <color rgba="1.0 1.0 1.0 1.0"/>
  </material>
  <material name="blue">
    <color rgba="0.5 0.5 1 1.0"/>
  </material>
  <link name="world"/>
  <!-- Stand: connects world to optimo_base_link -->
  <joint name="optimo_world_to_stand" type="fixed">
    <parent link="world"/>
    <child link="optimo_stand"/>
    <origin rpy="0 0 0" xyz="0 0 0"/>
  </joint>
  <link name="optimo_stand">
    <visual>
      <origin rpy="0 0 0" xyz="0 0 -0.5"/>
      <geometry>
        <box size="0.5 0.5 1"/>
      </geometry>
      <material name="white"/>
    </visual>
    <collision>
      <origin rpy="0 0 0" xyz="0 0 -0.5"/>
      <geometry>
        <box size="0.5 0.5 1"/>
      </geometry>
    </collision>
  </link>
  <joint name="optimo_stand_to_base_link" type="fixed">
    <parent link="optimo_stand"/>
    <child link="optimo_base_link"/>
    <origin rpy="0 0 0" xyz="0 0 0"/>
  </joint>
  <link name="optimo_base_link"/>
  <joint name="optimo_base_link_to_link0" type="fixed">
    <parent link="optimo_base_link"/>
    <child link="optimo_link0"/>
    <origin rpy="0 0 0" xyz="0 0 .27"/>
  </joint>
  <!-- Base Link -->
  <link name="optimo_link0">
    <visual>
      <geometry>
        <mesh filename="meshes/link0.stl"/>
      </geometry>
      <material name="blue"/>
    </visual>
    <collision>
      <geometry>
        <mesh filename="meshes/col0.stl"/>
      </geometry>
    </collision>
    <inertial>
      <origin xyz="0 0 0"/>
      <mass value="1"/>
      <inertia ixx="0" ixy="0.0" ixz="0.0" iyy="0" iyz="0.0" izz="0"/>
    </inertial>
  </link>
  <joint name="optimo_joint1" type="revolute">
    <origin rpy="0 0 0" xyz="0 0 0"/>
    <parent link="optimo_link0"/>
    <child link="optimo_link1"/>
    <axis xyz="0 0 1"/>
    <limit effort="79" lower="-2.0943951012" upper="2.0943951012" velocity="10"/>
    <dynamics damping=".5" friction=".2"/>
  </joint>
  <link name="optimo_link1">
    <visual>
      <origin rpy="1.5707963267948966 0 0" xyz="0 0 0"/>
      <geometry>
        <mesh filename="meshes/link1.stl"/>
      </geometry>
      <material name="white"/>
    </visual>
    <collision>
      <origin rpy="1.5707963267948966 0 0" xyz="0 0 0"/>
      <geometry>
        <mesh filename="meshes/col1.stl"/>
      </geometry>
    </collision>
    <inertial>
      <origin xyz="0 -0.01549 -0.01635 "/>
      <mass value="4.152"/>
      <inertia ixx="0.01" ixy="0" ixz="0" iyy="0.01" iyz="0" izz="0.006"/>
    </inertial>
  </link>
  <joint name="optimo_joint2" type="revolute">
    <origin rpy="1.5707963267948966 0 0" xyz="0 0 0"/>
    <parent link="optimo_link1"/>
    <child link="optimo_link2"/>
    <axis xyz="0 0 1"/>
    <limit effort="95" lower="1.0471975506" upper="3.8397243521999997" velocity="10"/>
    <dynamics damping=".5" friction=".2"/>
  </joint>
  <link name="optimo_link2">
    <visual>
      <origin rpy="1.5707963267948966 0 0" xyz="0 0 0"/>
      <geometry>
        <mesh filename="meshes/link2.stl"/>
      </geometry>
      <material name="blue"/>
    </visual>
    <collision>
      <origin rpy="1.5707963267948966 0 0" xyz="0 0 0"/>
      <geometry>
        <mesh filename="meshes/col2.stl"/>
      </geometry>
    </collision>
    <inertial>
      <origin xyz="0 -0.05677 -0.05063 "/>
      <mass value="1.72"/>
      <inertia ixx="0.004" ixy="0" ixz="0" iyy="0.003" iyz="0" izz="0.005"/>
    </inertial>
  </link>
  <joint name="optimo_joint3" type="revolute">
    <origin rpy="1.5707963267948966 0 0" xyz="0 -0.4 0"/>
    <parent link="optimo_link2"/>
    <child link="optimo_link3"/>
    <axis xyz="0 0 1"/>
    <limit effort="32" lower="-2.0943951012" upper="2.0943951012" velocity="10"/>
    <dynamics damping=".5" friction=".2"/>
  </joint>
  <link name="optimo_link3">
    <visual>
      <origin rpy="-1.5707963267948966 0 0" xyz="0 0 0"/>
      <geometry>
        <mesh filename="meshes/link3.stl"/>
      </geometry>
      <material name="white"/>
    </visual>
    <collision>
      <origin rpy="-1.5707963267948966 0 0" xyz="0 0 0"/>
      <geometry>
        <mesh filename="meshes/col3.stl"/>
      </geometry>
    </collision>
    <inertial>
      <origin xyz="0 0 -0.098"/>
      <mass value="4.310"/>
      <inertia ixx="0.013" ixy="0" ixz="0" iyy="0.013" iyz="0" izz="0.003"/>
    </inertial>
  </link>
  <joint name="optimo_joint4" type="revolute">
    <origin rpy="-1.5707963267948966 0 0" xyz="0 0 0"/>
    <parent link="optimo_link3"/>
    <child link="optimo_link4"/>
    <axis xyz="0 0 1"/>
    <limit effort="40" lower="-2.53072741395" upper="2.53072741395" velocity="10"/>
    <dynamics damping=".5" friction=".2"/>
  </joint>
  <link name="optimo_link4">
    <visual>
      <origin rpy="1.5707963267948966 0 0" xyz="0 0 0"/>
      <geometry>
        <mesh filename="meshes/link4.stl"/>
      </geometry>
      <material name="blue"/>
    </visual>
    <collision>
      <origin rpy="1.5707963267948966 0 0" xyz="0 0 0"/>
      <geometry>
        <mesh filename="meshes/col4.stl"/>
      </geometry>
    </collision>
    <inertial>
      <origin xyz="-.00001 -0.0688 0.048852"/>
      <mass value="1.09"/>
      <inertia ixx="0.004" ixy="0" ixz="0" iyy="0.0008" iyz="0" izz="0.004"/>
    </inertial>
  </link>
  <joint name="optimo_joint5" type="revolute">
    <origin rpy="1.5707963267948966 0 0" xyz="0 -0.4 0"/>
    <parent link="optimo_link4"/>
    <child link="optimo_link5"/>
    <axis xyz="0 0 1"/>
    <limit effort="15" lower="-2.6179938765" upper="2.6179938765" velocity="10"/>
    <dynamics damping=".5" friction=".2"/>
  </joint>
  <link name="optimo_link5">
    <visual>
      <origin rpy="-1.5707963267948966 0 0" xyz="0 0 0"/>
      <geometry>
        <mesh filename="meshes/link5.stl"/>
      </geometry>
      <material name="white"/>
    </visual>
    <collision>
      <origin rpy="-1.5707963267948966 0 0" xyz="0 0 0"/>
      <geometry>
        <mesh filename="meshes/col5.stl"/>
      </geometry>
    </collision>
    <inertial>
      <origin xyz="0 0.008 -.085"/>
      <mass value="2.23"/>
      <inertia ixx="0.005" ixy="0" ixz="0" iyy="0.005" iyz="0" izz="0.002"/>
    </inertial>
  </link>
  <joint name="optimo_joint6" type="revolute">
    <origin rpy="-1.5707963267948966 0 0" xyz="0 0 0"/>
    <parent link="optimo_link5"/>
    <child link="optimo_link6"/>
    <axis xyz="0 0 1"/>
    <limit effort="15" lower="-2.0943951012" upper="2.0943951012" velocity="10"/>
    <dynamics damping=".5" friction=".2"/>
  </joint>
  <link name="optimo_link6">
    <visual>
      <origin rpy="1.5707963267948966 0 0" xyz="0 0 0"/>
      <geometry>
        <mesh filename="meshes/link6.stl"/>
      </geometry>
      <material name="blue"/>
    </visual>
    <collision>
      <origin rpy="1.5707963267948966 0 0" xyz="0 0 0"/>
      <geometry>
        <mesh filename="meshes/col6.stl"/>
      </geometry>
    </collision>
    <inertial>
      <origin xyz="0  -0.010855 0"/>
      <mass value="1.138"/>
      <inertia ixx="0.0006" ixy="0" ixz="0" iyy="0.0006" iyz="0" izz="0.0005"/>
    </inertial>
  </link>
  <joint name="optimo_joint7" type="revolute">
    <origin rpy="1.5707963267948966 0 0" xyz="0 0 0"/>
    <parent link="optimo_link6"/>
    <child link="optimo_link7"/>
    <axis xyz="0 0 1"/>
    <limit effort="15" lower="-2.0943951012" upper="2.0943951012" velocity="10"/>
    <dynamics damping=".5" friction=".2"/>
  </joint>
  <link name="optimo_link7">
    <visual>
      <geometry>
        <mesh filename="meshes/link7.stl"/>
      </geometry>
      <material name="white"/>
    </visual>
    <collision>
      <geometry>
        <mesh filename="meshes/col7.stl"/>
      </geometry>
    </collision>
    <inertial>
      <origin xyz="0 0 0.1"/>
      <mass value=".88"/>
      <inertia ixx="0.0007" ixy="0" ixz="0" iyy="0.0007" iyz="0" izz="0.0003"/>
    </inertial>
  </link>
  <joint name="optimo_ee_joint" type="fixed">
    <origin rpy="0 0 0" xyz="0 0 0.15"/>
    <parent link="optimo_link7"/>
    <child link="optimo_end_effector"/>
  </joint>
  <link name="optimo_end_effector"/>
  <ros2_control name="OptimoHardwareInterface" type="system">
    <joint name="optimo_joint1">
      <command_interface name="position"/>
      <command_interface name="velocity"/>
      <command_interface name="effort">
        <param name="min">-79</param>
        <param name="max">79</param>
      </command_interface>
      <state_interface name="position"/>
      <state_interface name="velocity"/>
      <state_interface name="effort"/>
    </joint>
    <joint name="optimo_joint2">
      <command_interface name="position"/>
      <command_interface name="velocity"/>
      <command_interface name="effort">
        <param name="min">-95</param>
        <param name="max">95</param>
      </command_interface>
      <state_interface name="position"/>
      <state_interface name="velocity"/>
      <state_interface name="effort"/>
    </joint>
    <joint name="optimo_joint3">
      <command_interface name="position"/>
      <command_interface name="velocity"/>
      <command_interface name="effort">
        <param name="min">-32</param>
        <param name="max">32</param>
      </command_interface>
      <state_interface name="position"/>
      <state_interface name="velocity"/>
      <state_interface name="effort"/>
    </joint>
    <joint name="optimo_joint4">
      <command_interface name="position"/>
      <command_interface name="velocity"/>
      <command_interface name="effort">
        <param name="min">-40</param>
        <param name="max">40</param>
      </command_interface>
      <state_interface name="position"/>
      <state_interface name="velocity"/>
      <state_interface name="effort"/>
    </joint>
    <joint name="optimo_joint5">
      <command_interface name="position"/>
      <command_interface name="velocity"/>
      <command_interface name="effort">
        <param name="min">-15</param>
        <param name="max">15</param>
      </command_interface>
      <state_interface name="position"/>
      <state_interface name="velocity"/>
      <state_interface name="effort"/>
    </joint>
    <joint name="optimo_joint6">
      <command_interface name="position"/>
      <command_interface name="velocity"/>
      <command_interface name="effort">
        <param name="min">-15</param>
        <param name="max">15</param>
      </command_interface>
      <state_interface name="position"/>
      <state_interface name="velocity"/>
      <state_interface name="effort"/>
    </joint>
    <joint name="optimo_joint7">
      <command_interface name="position"/>
      <command_interface name="velocity"/>
      <command_interface name="effort">
        <param name="min">-15</param>
        <param name="max">15</param>
      </command_interface>
      <state_interface name="position"/>
      <state_interface name="velocity"/>
      <state_interface name="effort"/>
    </joint>
  </ros2_control>
</robot>
