<?xml version="1.0" ?>
<!-- =================================================================================== -->
<!-- |    This document was autogenerated by xacro from rpc_ros/description/optimo_description/urdf/optimo.urdf.xacro | -->
<!-- |    EDITING THIS FILE BY HAND IS NOT RECOMMENDED                                 | -->
<!-- =================================================================================== -->
<!-- URDF for the standalone Optimo 7-DOF arm, including controls -->
<robot name="optimo">
  <material name="white">
    <color rgba="1.0 1.0 1.0 1.0"/>
  </material>
  <material name="blue">
    <color rgba="0.5 0.5 1 1.0"/>
  </material>
  <link name="world"/>
  <joint name="world_to_stand" type="fixed">
    <parent link="world"/>
    <child link="stand"/>
    <origin rpy="0 0 0" xyz="0 0 0"/>
  </joint>
  <link name="stand">
    <visual>
      <origin rpy="0 0 0" xyz="0 0 -0.5"/>
      <geometry>
        <box size="0.5 0.5 1"/>
      </geometry>
      <material name="white"/>
    </visual>
    <collision>
      <origin rpy="0 0 0" xyz="0 0 -0.5"/>
      <geometry>
        <box size="0.5 0.5 1"/>
      </geometry>
    </collision>
  </link>
  <joint name="stand_to_base_link" type="fixed">
    <parent link="stand"/>
    <child link="base_link"/>
    <origin rpy="0 0 0" xyz="0 0 0"/>
  </joint>
  <link name="base_link"/>
  <joint name="base_link_to_link0" type="fixed">
    <parent link="base_link"/>
    <child link="link0"/>
    <origin rpy="0 0 0" xyz="0 0 .27"/>
  </joint>
  <!-- Base Link -->
  <link name="link0">
    <visual>
      <geometry>
        <mesh filename="package://optimo_description/meshes/link0.stl"/>
      </geometry>
      <material name="blue"/>
    </visual>
    <collision>
      <geometry>
        <mesh filename="package://optimo_description/meshes/col0.stl"/>
      </geometry>
    </collision>
    <inertial>
      <!-- Doesn't matter, just placeholder values -->
      <origin xyz="0 0 0"/>
      <mass value="1"/>
      <inertia ixx="0" ixy="0.0" ixz="0.0" iyy="0" iyz="0.0" izz="0"/>
    </inertial>
  </link>
  <joint name="joint1" type="revolute">
    <origin rpy="0 0 0" xyz="0 0 0"/>
    <parent link="link0"/>
    <child link="link1"/>
    <axis xyz="0 0 1"/>
    <limit effort="95" lower="-2.0943951012" upper="2.0943951012" velocity="1.745329251"/>
    <dynamics damping=".5" friction=".2"/>
  </joint>
  <link name="link1">
    <visual>
      <origin rpy="1.5707963267948966 0 0" xyz="0 0 0"/>
      <geometry>
        <mesh filename="package://optimo_description/meshes/link1.stl"/>
      </geometry>
      <material name="white"/>
    </visual>
    <collision>
      <origin rpy="1.5707963267948966 0 0" xyz="0 0 0"/>
      <geometry>
        <mesh filename="package://optimo_description/meshes/col1.stl"/>
      </geometry>
    </collision>
    <inertial>
      <origin xyz="0 -0.01635 0.01549"/>
      <mass value="4.14"/>
      <inertia ixx="0.010001" ixy="0.000017" ixz="-0.000010" iyy="0.007494" iyz="0.000213" izz="0.009939"/>
    </inertial>
  </link>
  <joint name="joint2" type="revolute">
    <origin rpy="1.5707963267948966 0 0" xyz="0 0 0"/>
    <parent link="link1"/>
    <child link="link2"/>
    <axis xyz="0 0 1"/>
    <limit effort="95" lower="1.0471975506" upper="3.8397243521999997" velocity="1.745329251"/>
    <dynamics damping=".5" friction=".2"/>
  </joint>
  <link name="link2">
    <visual>
      <origin rpy="1.5707963267948966 0 0" xyz="0 0 0"/>
      <geometry>
        <mesh filename="package://optimo_description/meshes/link2.stl"/>
      </geometry>
      <material name="blue"/>
    </visual>
    <collision>
      <origin rpy="1.5707963267948966 0 0" xyz="0 0 0"/>
      <geometry>
        <mesh filename="package://optimo_description/meshes/col2.stl"/>
      </geometry>
    </collision>
    <inertial>
      <origin xyz="0 -0.05063 0.05677"/>
      <mass value="1.72"/>
      <inertia ixx="0.005694" ixy="0" ixz="0" iyy="0.005902" iyz="0.001353" izz="0.002415"/>
    </inertial>
  </link>
  <joint name="joint3" type="revolute">
    <origin rpy="1.5707963267948966 0 0" xyz="0 -0.4 0"/>
    <parent link="link2"/>
    <child link="link3"/>
    <axis xyz="0 0 1"/>
    <limit effort="40" lower="-2.0943951012" upper="2.0943951012" velocity="2.6179938765"/>
    <dynamics damping=".5" friction=".2"/>
  </joint>
  <link name="link3">
    <visual>
      <origin rpy="-1.5707963267948966 0 0" xyz="0 0 0"/>
      <geometry>
        <mesh filename="package://optimo_description/meshes/link3.stl"/>
      </geometry>
      <material name="white"/>
    </visual>
    <collision>
      <origin rpy="-1.5707963267948966 0 0" xyz="0 0 0"/>
      <geometry>
        <mesh filename="package://optimo_description/meshes/col3.stl"/>
      </geometry>
    </collision>
    <inertial>
      <origin xyz="-0.000039 0.098 0"/>
      <mass value="4.13"/>
      <inertia ixx="0.012989" ixy="-0.000015" ixz="-0.000003" iyy="0.002584" iyz="0.000632" izz="0.013050"/>
    </inertial>
  </link>
  <joint name="joint4" type="revolute">
    <origin rpy="-1.5707963267948966 0 0" xyz="0 0 0"/>
    <parent link="link3"/>
    <child link="link4"/>
    <axis xyz="0 0 1"/>
    <limit effort="40" lower="-2.53072741395" upper="2.53072741395" velocity="2.6179938765"/>
    <dynamics damping=".5" friction=".2"/>
  </joint>
  <link name="link4">
    <visual>
      <origin rpy="1.5707963267948966 0 0" xyz="0 0 0"/>
      <geometry>
        <mesh filename="package://optimo_description/meshes/link4.stl"/>
      </geometry>
      <material name="blue"/>
    </visual>
    <collision>
      <origin rpy="1.5707963267948966 0 0" xyz="0 0 0"/>
      <geometry>
        <mesh filename="package://optimo_description/meshes/col4.stl"/>
      </geometry>
    </collision>
    <inertial>
      <origin xyz="-0.000010 0.048852 0.068800"/>
      <mass value="1.09"/>
      <inertia ixx="0.033673" ixy="-0.00046473" ixz="-0.00000072068" iyy="0.00108897820" iyz="0.000095301" izz="0.0338768"/>
    </inertial>
  </link>
  <joint name="joint5" type="revolute">
    <origin rpy="1.5707963267948966 0 0" xyz="0 -0.4 0"/>
    <parent link="link4"/>
    <child link="link5"/>
    <axis xyz="0 0 1"/>
    <limit effort="15" lower="-2.6179938765" upper="2.6179938765" velocity="3.1415926518"/>
    <dynamics damping=".5" friction=".2"/>
  </joint>
  <link name="link5">
    <visual>
      <origin rpy="-1.5707963267948966 0 0" xyz="0 0 0"/>
      <geometry>
        <mesh filename="package://optimo_description/meshes/link5.stl"/>
      </geometry>
      <material name="white"/>
    </visual>
    <collision>
      <origin rpy="-1.5707963267948966 0 0" xyz="0 0 0"/>
      <geometry>
        <mesh filename="package://optimo_description/meshes/col5.stl"/>
      </geometry>
    </collision>
    <inertial>
      <origin xyz="0.001262 0.085 0.008"/>
      <mass value="1.92"/>
      <inertia ixx="0.00093167" ixy="0.00000007143" ixz="0" iyy="0.00080219" iyz="-0.000030258" izz="0.00073250"/>
    </inertial>
  </link>
  <joint name="joint6" type="revolute">
    <origin rpy="-1.5707963267948966 0 0" xyz="0 0 0"/>
    <parent link="link5"/>
    <child link="link6"/>
    <axis xyz="0 0 1"/>
    <limit effort="15" lower="-2.0943951012" upper="2.0943951012" velocity="3.1415926518"/>
    <dynamics damping=".5" friction=".2"/>
  </joint>
  <link name="link6">
    <visual>
      <origin rpy="1.5707963267948966 0 0" xyz="0 0 0"/>
      <geometry>
        <mesh filename="package://optimo_description/meshes/link6.stl"/>
      </geometry>
      <material name="blue"/>
    </visual>
    <collision>
      <origin rpy="1.5707963267948966 0 0" xyz="0 0 0"/>
      <geometry>
        <mesh filename="package://optimo_description/meshes/col6.stl"/>
      </geometry>
    </collision>
    <inertial>
      <origin xyz="0 -0.000070 0.010855"/>
      <mass value="1.04"/>
      <inertia ixx="0.00093167" ixy="0.00000007143" ixz="0" iyy="0.00080219" iyz="-0.000030258" izz="0.00073250"/>
    </inertial>
  </link>
  <joint name="joint7" type="revolute">
    <origin rpy="1.5707963267948966 0 0" xyz="0 0 0"/>
    <parent link="link6"/>
    <child link="link7"/>
    <axis xyz="0 0 1"/>
    <limit effort="15" lower="-2.0943951012" upper="2.0943951012" velocity="3.1415926518"/>
    <dynamics damping=".5" friction=".2"/>
  </joint>
  <link name="link7">
    <visual>
      <geometry>
        <mesh filename="package://optimo_description/meshes/link7.stl"/>
      </geometry>
      <material name="white"/>
    </visual>
    <collision>
      <geometry>
        <mesh filename="package://optimo_description/meshes/col7.stl"/>
      </geometry>
    </collision>
    <inertial>
      <origin xyz="0 0 0.1"/>
      <mass value="0.88"/>
      <inertia ixx="0.005541" ixy="0.000045" ixz="0.000077" iyy="0.004779" iyz="0.000043" izz="0.001723"/>
    </inertial>
  </link>
  <joint name="ee_joint" type="fixed">
    <origin rpy="0 0 0" xyz="0 0 0.15"/>
    <parent link="link7"/>
    <child link="end_effector"/>
  </joint>
  <link name="end_effector"/>
  <ros2_control name="OptimoHardwareInterface" type="system">
    <joint name="joint1">
      <command_interface name="position"/>
      <command_interface name="velocity"/>
      <command_interface name="effort">
        <param name="min">-95</param>
        <param name="max">95</param>
      </command_interface>
      <state_interface name="position"/>
      <state_interface name="velocity"/>
      <state_interface name="effort"/>
    </joint>
    <joint name="joint2">
      <command_interface name="position"/>
      <command_interface name="velocity"/>
      <command_interface name="effort">
        <param name="min">-95</param>
        <param name="max">95</param>
      </command_interface>
      <state_interface name="position"/>
      <state_interface name="velocity"/>
      <state_interface name="effort"/>
    </joint>
    <joint name="joint3">
      <command_interface name="position"/>
      <command_interface name="velocity"/>
      <command_interface name="effort">
        <param name="min">-40</param>
        <param name="max">40</param>
      </command_interface>
      <state_interface name="position"/>
      <state_interface name="velocity"/>
      <state_interface name="effort"/>
    </joint>
    <joint name="joint4">
      <command_interface name="position"/>
      <command_interface name="velocity"/>
      <command_interface name="effort">
        <param name="min">-40</param>
        <param name="max">40</param>
      </command_interface>
      <state_interface name="position"/>
      <state_interface name="velocity"/>
      <state_interface name="effort"/>
    </joint>
    <joint name="joint5">
      <command_interface name="position"/>
      <command_interface name="velocity"/>
      <command_interface name="effort">
        <param name="min">-15</param>
        <param name="max">15</param>
      </command_interface>
      <state_interface name="position"/>
      <state_interface name="velocity"/>
      <state_interface name="effort"/>
    </joint>
    <joint name="joint6">
      <command_interface name="position"/>
      <command_interface name="velocity"/>
      <command_interface name="effort">
        <param name="min">-15</param>
        <param name="max">15</param>
      </command_interface>
      <state_interface name="position"/>
      <state_interface name="velocity"/>
      <state_interface name="effort"/>
    </joint>
    <joint name="joint7">
      <command_interface name="position"/>
      <command_interface name="velocity"/>
      <command_interface name="effort">
        <param name="min">-15</param>
        <param name="max">15</param>
      </command_interface>
      <state_interface name="position"/>
      <state_interface name="velocity"/>
      <state_interface name="effort"/>
    </joint>
  </ros2_control>
</robot>
